Workbook
Name NochesPorSemana: 'PARAMETROS'!$B$4
Name NochesPorMes: 'PARAMETROS'!$B$5
Name NochesPorMesAlt: 'PARAMETROS'!$B$6
Name CapacidadMaximaPersonasNoche: 'PARAMETROS'!$B$7
Name PersonasPorNocheBase: 'PARAMETROS'!$B$8
Name CopasPorPersona: 'PARAMETROS'!$B$9
Name VinosSimultaneos: 'PARAMETROS'!$B$10
Name PctBodegasSocias: 'PARAMETROS'!$B$13
Name PctCostoVinoPropio: 'PARAMETROS'!$B$14
Name CopasTeoricasPorBotella: 'PARAMETROS'!$B$15
Name Tier1Limite: 'PARAMETROS'!$B$18
Name Tier1Markup: 'PARAMETROS'!$B$19
Name Tier2Limite: 'PARAMETROS'!$B$20
Name Tier2Markup: 'PARAMETROS'!$B$21
Name Tier3Limite: 'PARAMETROS'!$B$22
Name Tier3Markup: 'PARAMETROS'!$B$23
Name Tier4Markup: 'PARAMETROS'!$B$24
Name RedondeoA: 'PARAMETROS'!$B$25
Name MermaCortesiaCopasPorBotella: 'PARAMETROS'!$B$28
Name MermaCatacionCopasPorBotella: 'PARAMETROS'!$B$29
Name MermaSobranteCopasPorBotella: 'PARAMETROS'!$B$30
Name MermaRoturasCopasPorBotella: 'PARAMETROS'!$B$31
Name Alquiler: 'PARAMETROS'!$B$34
Name SueldosCargas: 'PARAMETROS'!$B$35
Name PersonalApoyo5taNoche: 'PARAMETROS'!$B$36
Name Servicios: 'PARAMETROS'!$B$37
Name ServiciosExtra5taNoche: 'PARAMETROS'!$B$38
Name ImpuestosTasas: 'PARAMETROS'!$B$39
Name Seguro: 'PARAMETROS'!$B$40
Name Contador: 'PARAMETROS'!$B$41
Name MantenimientoDispenser: 'PARAMETROS'!$B$42
Name MarketingRedes: 'PARAMETROS'!$B$43
Name CostosFijosReferencia: 'PARAMETROS'!$B$44
Name CostoLimpiezaPorNoche: 'PARAMETROS'!$B$47
Name CostoReposicionCopaUnidad: 'PARAMETROS'!$B$48
Name PctRoturasCristaleria: 'PARAMETROS'!$B$49
Name PctComisionMedioPago: 'PARAMETROS'!$B$50
Name ClubSociosInicial: 'PARAMETROS'!$B$53
Name ClubSociosFinal: 'PARAMETROS'!$B$54
Name ClubSociosCuotaPromedio: 'PARAMETROS'!$B$55
Name PctClientesTapeo: 'PARAMETROS'!$B$56
Name IngresoEventosMensual: 'PARAMETROS'!$B$57
Name InflacionMensual: 'PARAMETROS'!$B$60
Name IdxEne: 'PARAMETROS'!$B$64
Name IdxFeb: 'PARAMETROS'!$D$64
Name IdxMar: 'PARAMETROS'!$B$65
Name IdxAbr: 'PARAMETROS'!$D$65
Name IdxMay: 'PARAMETROS'!$B$66
Name IdxJun: 'PARAMETROS'!$D$66
Name IdxJul: 'PARAMETROS'!$B$67
Name IdxAgo: 'PARAMETROS'!$D$67
Name IdxSep: 'PARAMETROS'!$B$68
Name IdxOct: 'PARAMETROS'!$D$68
Name IdxNov: 'PARAMETROS'!$B$69
Name IdxDic: 'PARAMETROS'!$D$69
Name PrecioVentaPromedio: 'CARTA SEMANAL'!$I$19
Name CostoPorCopaCompraPromedioTeorico: 'CARTA SEMANAL'!$I$20
Name PrecioGondolaPromedio: 'CARTA SEMANAL'!$I$21
Name RendimientoRealCopasPorBotella: 'MERMA Y CONTROL'!$B$9
Name TicketTapeoPromedio: 'TAPEO'!$B$19

Sheet PARAMETROS
A1: PARÁMETROS — 125cc Wine Bar (todo lo demás referencia esta hoja)
A2: Parámetro | B2: Valor | C2: Unidad | D2: Nota
A3: OPERACIÓN
A4: Noches por semana | B4: 5 | C4: noches | D4: Martes a sábado
A5: Noches por mes | B5: 21.5 | C5: noches | D5: 5 noches/sem × ~4,3 semanas
A6: Noches por mes — escenario 4 noches/sem | B6: =NochesPorSemana*0+NochesPorMes*4/NochesPorSemana | C6: noches | D6: Referencia para medir el efecto de la 5ta noche
A7: Capacidad máxima por noche | B7: 60 | C7: personas | D7: 20 personas × hasta 3 rotaciones
A8: Personas por noche (base, promedio) | B8: 40 | C8: personas | D8: Extremo conservador del rango 40–60 (20 pers. × 2 rotaciones)
A9: Copas por persona | B9: 2.2 | C9: copas | D9: Conservador dentro del rango 2–3
A10: Vinos simultáneos en carta | B10: 14 | C10: vinos | D10: Rotación semanal → 52 etiquetas distintas/mes
A12: CARTA Y COSTO DE VINO
A13: % bodegas socias en carta (semilla actual) | B13: 0.5 | C13: % | D13: Editable — ejemplo de semilla ~50/50
A14: % costo del vino propio s/precio góndola | B14: 0.5 | C14: % | D14: Vino de bodega socia = costo $0
A15: Copas teóricas por botella | B15: 6 | C15: copas | D15: 750 ml ÷ 125 cc
A17: MARKUP ESCALONADO (precio de venta por copa)
A18: Límite banda 1 (precio góndola) | B18: 30000 | C18: $
A19: Markup banda 1 (hasta límite 1) | B19: 1.7 | C19: x
A20: Límite banda 2 (precio góndola) | B20: 60000 | C20: $
A21: Markup banda 2 (hasta límite 2) | B21: 1.6 | C21: x
A22: Límite banda 3 (precio góndola) | B22: 90000 | C22: $
A23: Markup banda 3 (hasta límite 3) | B23: 1.5 | C23: x
A24: Markup banda 4 (sobre límite 3) | B24: 1.25 | C24: x
A25: Redondeo del precio final | B25: 50 | C25: $ | D25: Redondeo al múltiplo más cercano (MROUND)
A27: MERMA — copas perdidas por botella (rendimiento real)
A28: Cortesía a cliente / prensa | B28: 0.15 | C28: copas/bot.
A29: Catación del sommelier | B29: 0.1 | C29: copas/bot.
A30: Sobrante de botella abierta no vendido | B30: 0.2 | C30: copas/bot. | D30: Mejorado por 5 noches (mayor rotación) + dispenser Redsack (menor oxidación)
A31: Roturas de cristalería (equivalente) | B31: 0.05 | C31: copas/bot.
A33: COSTOS FIJOS MENSUALES (desglose editable)
A34: Alquiler | B34: 900000 | C34: $/mes
A35: Sueldos y cargas sociales (base, 4 noches) | B35: 1600000 | C35: $/mes
A36: Personal de apoyo — 5ta noche | B36: 150000 | C36: $/mes | D36: Escala con la 5ta noche (turno extra de sala)
A37: Servicios (luz/gas/agua/internet) | B37: 180000 | C37: $/mes
A38: Servicios extra — 5ta noche | B38: 15000 | C38: $/mes | D38: Escala con la 5ta noche
A39: Impuestos y tasas municipales | B39: 90000 | C39: $/mes
A40: Seguro | B40: 35000 | C40: $/mes
A41: Contador | B41: 70000 | C41: $/mes
A42: Mantenimiento dispenser Redsack | B42: 40000 | C42: $/mes
A43: Marketing / redes | B43: 60000 | C43: $/mes
A44: Costo fijo mensual de referencia (piso del dueño, a validar) | B44: 3000000 | C44: $/mes | D44: Punto de partida — compará contra el total calculado en hoja 5
...

Sheet CARTA SEMANAL
A1: CARTA SEMANAL — 14 vinos simultáneos (renovación semanal)
A2: Bodega | B2: Etiqueta | C2: Varietal | D2: Precio góndola | E2: Origen | F2: Costo real botella | G2: Costo por copa (teór.) | H2: Precio venta calculado | I2: Precio redondeado | J2: Margen $ por copa | K2: Margen % | L2: Copas est. venta/sem | M2: Ingreso proyectado | N2: Contribución marginal
A3: Reinero | B3: Reinero Nazareno Malbec | C3: 100% Malbec | D3: 9900 | E3: socia | F3: =IF(E3="socia",0,D3*PctCostoVinoPropio) | G3: =F3/CopasTeoricasPorBotella | H3: =(D3/CopasTeoricasPorBotella)*IF(D3<=Tier1Limite,Tier1Markup,IF(D3<=Tier2Limite,Tier2Markup,IF(D3<=Tier3Limite,Tier3Markup,Tier4Markup))) | I3: =MROUND(H3,RedondeoA) | J3: =I3-G3 | K3: =J3/I3 | L3: =(PersonasPorNocheBase*CopasPorPersona*NochesPorSemana)/VinosSimultaneos | M3: =L3*I3 | N3: =L3*J3
A4: Dharma Wines | B4: Kamala Pinot Noir | C4: 100% Pinot Noir | D4: 14600 | E4: compra | F4: =IF(E4="socia",0,D4*PctCostoVinoPropio) | G4: =F4/CopasTeoricasPorBotella | H4: =(D4/CopasTeoricasPorBotella)*IF(D4<=Tier1Limite,Tier1Markup,IF(D4<=Tier2Limite,Tier2Markup,IF(D4<=Tier3Limite,Tier3Markup,Tier4Markup))) | I4: =MROUND(H4,RedondeoA) | J4: =I4-G4 | K4: =J4/I4 | L4: =(PersonasPorNocheBase*CopasPorPersona*NochesPorSemana)/VinosSimultaneos | M4: =L4*I4 | N4: =L4*J4
A5: Ricominciare | B5: Ricominciare Malbec | C5: 100% Malbec | D5: 16360 | E5: socia | F5: =IF(E5="socia",0,D5*PctCostoVinoPropio) | G5: =F5/CopasTeoricasPorBotella | H5: =(D5/CopasTeoricasPorBotella)*IF(D5<=Tier1Limite,Tier1Markup,IF(D5<=Tier2Limite,Tier2Markup,IF(D5<=Tier3Limite,Tier3Markup,Tier4Markup))) | I5: =MROUND(H5,RedondeoA) | J5: =I5-G5 | K5: =J5/I5 | L5: =(PersonasPorNocheBase*CopasPorPersona*NochesPorSemana)/VinosSimultaneos | M5: =L5*I5 | N5: =L5*J5
A6: Dharma Wines | B6: Kamala Cabernet Franc | C6: 100% Cabernet Franc | D6: 13700 | E6: compra | F6: =IF(E6="socia",0,D6*PctCostoVinoPropio) | G6: =F6/CopasTeoricasPorBotella | H6: =(D6/CopasTeoricasPorBotella)*IF(D6<=Tier1Limite,Tier1Markup,IF(D6<=Tier2Limite,Tier2Markup,IF(D6<=Tier3Limite,Tier3Markup,Tier4Markup))) | I6: =MROUND(H6,RedondeoA) | J6: =I6-G6 | K6: =J6/I6 | L6: =(PersonasPorNocheBase*CopasPorPersona*NochesPorSemana)/VinosSimultaneos | M6: =L6*I6 | N6: =L6*J6
A7: Reinero | B7: Reinero Reserva Blend | C7: Malbec · Cabernet Franc · Merlot | D7: 12200 | E7: socia | F7: =IF(E7="socia",0,D7*PctCostoVinoPropio) | G7: =F7/CopasTeoricasPorBotella | H7: =(D7/CopasTeoricasPorBotella)*IF(D7<=Tier1Limite,Tier1Markup,IF(D7<=Tier2Limite,Tier2Markup,IF(D7<=Tier3Limite,Tier3Markup,Tier4Markup))) | I7: =MROUND(H7,RedondeoA) | J7: =I7-G7 | K7: =J7/I7 | L7: =(PersonasPorNocheBase*CopasPorPersona*NochesPorSemana)/VinosSimultaneos | M7: =L7*I7 | N7: =L7*J7
A8: Marchiori & Barraud | B8: Marchiori & Barraud Cabernet Sauvignon | C8: 100% Cabernet Sauvignon | D8: 12600 | E8: compra | F8: =IF(E8="socia",0,D8*PctCostoVinoPropio) | G8: =F8/CopasTeoricasPorBotella | H8: =(D8/CopasTeoricasPorBotella)*IF(D8<=Tier1Limite,Tier1Markup,IF(D8<=Tier2Limite,Tier2Markup,IF(D8<=Tier3Limite,Tier3Markup,Tier4Markup))) | I8: =MROUND(H8,RedondeoA) | J8: =I8-G8 | K8: =J8/I8 | L8: =(PersonasPorNocheBase*CopasPorPersona*NochesPorSemana)/VinosSimultaneos | M8: =L8*I8 | N8: =L8*J8
A9: Alta Vista | B9: Alta Vista Estate Pinot Noir | C9: 100% Pinot Noir | D9: 15000 | E9: socia | F9: =IF(E9="socia",0,D9*PctCostoVinoPropio) | G9: =F9/CopasTeoricasPorBotella | H9: =(D9/CopasTeoricasPorBotella)*IF(D9<=Tier1Limite,Tier1Markup,IF(D9<=Tier2Limite,Tier2Markup,IF(D9<=Tier3Limite,Tier3Markup,Tier4Markup))) | I9: =MROUND(H9,RedondeoA) | J9: =I9-G9 | K9: =J9/I9 | L9: =(PersonasPorNocheBase*CopasPorPersona*NochesPorSemana)/VinosSimultaneos | M9: =L9*I9 | N9: =L9*J9
A10: Alta Vista | B10: VIVE Red Blend | C10: Malbec · Cabernet Sauvignon · Syrah | D10: 12500 | E10: compra | F10: =IF(E10="socia",0,D10*PctCostoVinoPropio) | G10: =F10/CopasTeoricasPorBotella | H10: =(D10/CopasTeoricasPorBotella)*IF(D10<=Tier1Limite,Tier1Markup,IF(D10<=Tier2Limite,Tier2Markup,IF(D10<=Tier3Limite,Tier3Markup,Tier4Markup))) | I10: =MROUND(H10,RedondeoA) | J10: =I10-G10 | K10: =J10/I10 | L10: =(PersonasPorNocheBase*CopasPorPersona*NochesPorSemana)/VinosSimultaneos | M10: =L10*I10 | N10: =L10*J10
A11: Gimenez Riili | B11: De Nos Blend de Blancas | C11: Pedro Ximénez 65% · Riesling 35% | D11: 11700 | E11: socia | F11: =IF(E11="socia",0,D11*PctCostoVinoPropio) | G11: =F11/CopasTeoricasPorBotella | H11: =(D11/CopasTeoricasPorBotella)*IF(D11<=Tier1Limite,Tier1Markup,IF(D11<=Tier2Limite,Tier2Markup,IF(D11<=Tier3Limite,Tier3Markup,Tier4Markup))) | I11: =MROUND(H11,RedondeoA) | J11: =I11-G11 | K11: =J11/I11 | L11: =(PersonasPorNocheBase*CopasPorPersona*NochesPorSemana)/VinosSimultaneos | M11: =L11*I11 | N11: =L11*J11
A12: Kaiken | B12: Kaiken Ultra Chardonnay | C12: 100% Chardonnay | D12: 24500 | E12: compra | F12: =IF(E12="socia",0,D12*PctCostoVinoPropio) | G12: =F12/CopasTeoricasPorBotella | H12: =(D12/CopasTeoricasPorBotella)*IF(D12<=Tier1Limite,Tier1Markup,IF(D12<=Tier2Limite,Tier2Markup,IF(D12<=Tier3Limite,Tier3Markup,Tier4Markup))) | I12: =MROUND(H12,RedondeoA) | J12: =I12-G12 | K12: =J12/I12 | L12: =(PersonasPorNocheBase*CopasPorPersona*NochesPorSemana)/VinosSimultaneos | M12: =L12*I12 | N12: =L12*J12
A13: Gimenez Riili | B13: Nietos Compañeros Blend Rosado | C13: Blend de rosados | D13: 16100 | E13: socia | F13: =IF(E13="socia",0,D13*PctCostoVinoPropio) | G13: =F13/CopasTeoricasPorBotella | H13: =(D13/CopasTeoricasPorBotella)*IF(D13<=Tier1Limite,Tier1Markup,IF(D13<=Tier2Limite,Tier2Markup,IF(D13<=Tier3Limite,Tier3Markup,Tier4Markup))) | I13: =MROUND(H13,RedondeoA) | J13: =I13-G13 | K13: =J13/I13 | L13: =(PersonasPorNocheBase*CopasPorPersona*NochesPorSemana)/VinosSimultaneos | M13: =L13*I13 | N13: =L13*J13
A14: Uruco Wines | B14: Finca El Peral Rosé | C14: Cabernet Franc | D14: 12000 | E14: compra | F14: =IF(E14="socia",0,D14*PctCostoVinoPropio) | G14: =F14/CopasTeoricasPorBotella | H14: =(D14/CopasTeoricasPorBotella)*IF(D14<=Tier1Limite,Tier1Markup,IF(D14<=Tier2Limite,Tier2Markup,IF(D14<=Tier3Limite,Tier3Markup,Tier4Markup))) | I14: =MROUND(H14,RedondeoA) | J14: =I14-G14 | K14: =J14/I14 | L14: =(PersonasPorNocheBase*CopasPorPersona*NochesPorSemana)/VinosSimultaneos | M14: =L14*I14 | N14: =L14*J14
... A16: Collovatti | B16: Collovati Malbec | C16: 100% Malbec | D16: 20150 | E16: compra | F16: =IF(E16="socia",0,D16*PctCostoVinoPropio) | G16: =F16/CopasTeoricasPorBotella | H16: =(D16/CopasTeoricasPorBotella)*IF(D16<=Tier1Limite,Tier1Markup,IF(D16<=Tier2Limite,Tier2Markup,IF(D16<=Tier3Limite,Tier3Markup,Tier4Markup))) | I16: =MROUND(H16,RedondeoA) | J16: =I16-G16 | K16: =J16/I16 | L16: =(PersonasPorNocheBase*CopasPorPersona*NochesPorSemana)/VinosSimultaneos | M16: =L16*I16 | N16: =L16*J16
A17: TOTAL / PROMEDIO | D17: =AVERAGE(D3:D16) | F17: =AVERAGE(F3:F16) | G17: =AVERAGE(G3:G16) | H17: =AVERAGE(H3:H16) | I17: =AVERAGE(I3:I16) | J17: =AVERAGE(J3:J16) | K17: =AVERAGE(K3:K16) | L17: =SUM(L3:L16) | M17: =SUM(M3:M16) | N17: =SUM(N3:N16)
A19: Precio de venta promedio ponderado (referencia global) | I19: =AVERAGE(I3:I16)
A20: Costo por copa promedio — solo vinos de compra (teórico, referencia) | I20: =AVERAGEIF(E3:E16,"compra",G3:G16)
A21: Precio góndola promedio (referencia global, independiente del origen) | I21: =AVERAGE(D3:D16)

Sheet MERMA Y CONTROL
A1: MERMA Y CONTROL — rendimiento real de la botella
A2: RENDIMIENTO REAL POR BOTELLA (copas efectivamente vendibles)
A3: Copas teóricas por botella (750 ml ÷ 125 cc) | B3: =CopasTeoricasPorBotella
A4: Merma: cortesía a cliente / prensa | B4: =MermaCortesiaCopasPorBotella
A5: Merma: catación del sommelier | B5: =MermaCatacionCopasPorBotella
A6: Merma: sobrante de botella abierta no vendido | B6: =MermaSobranteCopasPorBotella
A7: Merma: roturas de cristalería (equivalente) | B7: =MermaRoturasCopasPorBotella
A8: Total merma (copas/botella) | B8: =SUM(B4:B7)
A9: Copas efectivamente vendibles por botella | B9: =B3-B8
A10: % de rendimiento real vs. teórico (6 copas) | B10: =B9/B3
A12: Con 5 noches de operación la rotación de cada botella abierta mejora (se vende más rápido, menos tiempo expuesta al aire) y el dispenser Redsack ya minimiza la oxidación por conservación con gas inerte — por eso la merma de 'sobrante no vendido' se cargó en el extremo bajo del rango posible en el escenario base, no en el extremo alto.
A15: IMPACTO EN EL MARGEN POR VINO (teórico 6 copas vs. rendimiento real)
A16: Bodega | B16: Etiqueta | C16: Costo botella | D16: Precio redondeado | E16: Costo copa (teórico, 6u) | F16: Costo copa (real) | G16: Margen $ (teórico) | H16: Margen $ (real) | I16: Margen % (real) | J16: Impacto margen $/copa | K16: Impacto margen p.p.
A17: ='CARTA SEMANAL'!A3 | B17: ='CARTA SEMANAL'!B3 | C17: ='CARTA SEMANAL'!F3 | D17: ='CARTA SEMANAL'!I3 | E17: ='CARTA SEMANAL'!G3 | F17: =C17/RendimientoRealCopasPorBotella | G17: ='CARTA SEMANAL'!J3 | H17: =D17-F17 | I17: =H17/D17 | J17: =H17-G17 | K17: =I17-'CARTA SEMANAL'!K3
A18: ='CARTA SEMANAL'!A4 | B18: ='CARTA SEMANAL'!B4 | C18: ='CARTA SEMANAL'!F4 | D18: ='CARTA SEMANAL'!I4 | E18: ='CARTA SEMANAL'!G4 | F18: =C18/RendimientoRealCopasPorBotella | G18: ='CARTA SEMANAL'!J4 | H18: =D18-F18 | I18: =H18/D18 | J18: =H18-G18 | K18: =I18-'CARTA SEMANAL'!K4
A19: ='CARTA SEMANAL'!A5 | B19: ='CARTA SEMANAL'!B5 | C19: ='CARTA SEMANAL'!F5 | D19: ='CARTA SEMANAL'!I5 | E19: ='CARTA SEMANAL'!G5 | F19: =C19/RendimientoRealCopasPorBotella | G19: ='CARTA SEMANAL'!J5 | H19: =D19-F19 | I19: =H19/D19 | J19: =H19-G19 | K19: =I19-'CARTA SEMANAL'!K5
A20: ='CARTA SEMANAL'!A6 | B20: ='CARTA SEMANAL'!B6 | C20: ='CARTA SEMANAL'!F6 | D20: ='CARTA SEMANAL'!I6 | E20: ='CARTA SEMANAL'!G6 | F20: =C20/RendimientoRealCopasPorBotella | G20: ='CARTA SEMANAL'!J6 | H20: =D20-F20 | I20: =H20/D20 | J20: =H20-G20 | K20: =I20-'CARTA SEMANAL'!K6
A21: ='CARTA SEMANAL'!A7 | B21: ='CARTA SEMANAL'!B7 | C21: ='CARTA SEMANAL'!F7 | D21: ='CARTA SEMANAL'!I7 | E21: ='CARTA SEMANAL'!G7 | F21: =C21/RendimientoRealCopasPorBotella | G21: ='CARTA SEMANAL'!J7 | H21: =D21-F21 | I21: =H21/D21 | J21: =H21-G21 | K21: =I21-'CARTA SEMANAL'!K7
A22: ='CARTA SEMANAL'!A8 | B22: ='CARTA SEMANAL'!B8 | C22: ='CARTA SEMANAL'!F8 | D22: ='CARTA SEMANAL'!I8 | E22: ='CARTA SEMANAL'!G8 | F22: =C22/RendimientoRealCopasPorBotella | G22: ='CARTA SEMANAL'!J8 | H22: =D22-F22 | I22: =H22/D22 | J22: =H22-G22 | K22: =I22-'CARTA SEMANAL'!K8
A23: ='CARTA SEMANAL'!A9 | B23: ='CARTA SEMANAL'!B9 | C23: ='CARTA SEMANAL'!F9 | D23: ='CARTA SEMANAL'!I9 | E23: ='CARTA SEMANAL'!G9 | F23: =C23/RendimientoRealCopasPorBotella | G23: ='CARTA SEMANAL'!J9 | H23: =D23-F23 | I23: =H23/D23 | J23: =H23-G23 | K23: =I23-'CARTA SEMANAL'!K9
A24: ='CARTA SEMANAL'!A10 | B24: ='CARTA SEMANAL'!B10 | C24: ='CARTA SEMANAL'!F10 | D24: ='CARTA SEMANAL'!I10 | E24: ='CARTA SEMANAL'!G10 | F24: =C24/RendimientoRealCopasPorBotella | G24: ='CARTA SEMANAL'!J10 | H24: =D24-F24 | I24: =H24/D24 | J24: =H24-G24 | K24: =I24-'CARTA SEMANAL'!K10
A25: ='CARTA SEMANAL'!A11 | B25: ='CARTA SEMANAL'!B11 | C25: ='CARTA SEMANAL'!F11 | D25: ='CARTA SEMANAL'!I11 | E25: ='CARTA SEMANAL'!G11 | F25: =C25/RendimientoRealCopasPorBotella | G25: ='CARTA SEMANAL'!J11 | H25: =D25-F25 | I25: =H25/D25 | J25: =H25-G25 | K25: =I25-'CARTA SEMANAL'!K11
A26: ='CARTA SEMANAL'!A12 | B26: ='CARTA SEMANAL'!B12 | C26: ='CARTA SEMANAL'!F12 | D26: ='CARTA SEMANAL'!I12 | E26: ='CARTA SEMANAL'!G12 | F26: =C26/RendimientoRealCopasPorBotella | G26: ='CARTA SEMANAL'!J12 | H26: =D26-F26 | I26: =H26/D26 | J26: =H26-G26 | K26: =I26-'CARTA SEMANAL'!K12
A27: ='CARTA SEMANAL'!A13 | B27: ='CARTA SEMANAL'!B13 | C27: ='CARTA SEMANAL'!F13 | D27: ='CARTA SEMANAL'!I13 | E27: ='CARTA SEMANAL'!G13 | F27: =C27/RendimientoRealCopasPorBotella | G27: ='CARTA SEMANAL'!J13 | H27: =D27-F27 | I27: =H27/D27 | J27: =H27-G27 | K27: =I27-'CARTA SEMANAL'!K13
A28: ='CARTA SEMANAL'!A14 | B28: ='CARTA SEMANAL'!B14 | C28: ='CARTA SEMANAL'!F14 | D28: ='CARTA SEMANAL'!I14 | E28: ='CARTA SEMANAL'!G14 | F28: =C28/RendimientoRealCopasPorBotella | G28: ='CARTA SEMANAL'!J14 | H28: =D28-F28 | I28: =H28/D28 | J28: =H28-G28 | K28: =I28-'CARTA SEMANAL'!K14
... A30: ='CARTA SEMANAL'!A16 | B30: ='CARTA SEMANAL'!B16 | C30: ='CARTA SEMANAL'!F16 | D30: ='CARTA SEMANAL'!I16 | E30: ='CARTA SEMANAL'!G16 | F30: =C30/RendimientoRealCopasPorBotella | G30: ='CARTA SEMANAL'!J16 | H30: =D30-F30 | I30: =H30/D30 | J30: =H30-G30 | K30: =I30-'CARTA SEMANAL'!K16
A31: PROMEDIO | C31: =AVERAGE(C17:C30) | D31: =AVERAGE(D17:D30) | E31: =AVERAGE(E17:E30) | F31: =AVERAGE(F17:F30) | G31: =AVERAGE(G17:G30) | H31: =AVERAGE(H17:H30) | I31: =AVERAGE(I17:I30) | J31: =AVERAGE(J17:J30) | K31: =AVERAGE(K17:K30)

Sheet TAPEO
A1: TAPEO — costeo por SKU
A2: Ítem | B2: Costo insumo / compra proveedor (por unidad de compra) | C2: Porciones por unidad de compra | D2: Costo por porción | E2: Precio de venta | F2: Margen $ | G2: Margen % | H2: Notas
A3: Tabla de carnes rojas (fiambre curado) | B3: 18000 | C3: 10 | D3: =B3/C3 | E3: 9500 | F3: =E3-D3 | G3: =F3/E3 | H3: Base: maridaje carnes rojas
A4: Quesos duros (parmesano/sardo, pieza) | B4: 14000 | C4: 12 | D4: =B4/C4 | E4: 7500 | F4: =E4-D4 | G4: =F4/E4 | H4: Base: maridaje quesos duros
A5: Quesos blandos (brie/cremoso, pieza) | B5: 12000 | C5: 10 | D5: =B5/C5 | E5: 7000 | F5: =E5-D5 | G5: =F5/E5 | H5: Base: maridaje quesos blandos
A6: Jamón crudo (paquete fetas) | B6: 16000 | C6: 8 | D6: =B6/C6 | E6: 8500 | F6: =E6-D6 | G6: =F6/E6 | H6: Base: maridaje jamón crudo
A7: Tabla mixta (para compartir) | B7: 22000 | C7: 6 | D7: =B7/C7 | E7: 12000 | F7: =E7-D7 | G7: =F7/E7 | H7: Base: maridaje tabla
A8: Fiambres surtidos | B8: 15000 | C8: 9 | D8: =B8/C8 | E8: 8000 | F8: =E8-D8 | G8: =F8/E8 | H8: Base: maridaje fiambres
A9: Salmón ahumado (porción) | B9: 21000 | C9: 7 | D9: =B9/C9 | E9: 11000 | F9: =E9-D9 | G9: =F9/E9 | H9: Base: maridaje salmón
A10: Mortadela con pistacho | B10: 11000 | C10: 10 | D10: =B10/C10 | E10: 6500 | F10: =E10-D10 | G10: =F10/E10 | H10: Base: maridaje mortadela
A11: Aceitunas gourmet (pote) | B11: 5500 | C11: 11 | D11: =B11/C11 | E11: 3200 | F11: =E11-D11 | G11: =F11/E11 | H11: Base: maridaje aceitunas
A12: Panera con dips | B12: 4200 | C12: 14 | D12: =B12/C12 | E12: 2800 | F12: =E12-D12 | G12: =F12/E12 | H12: Base: maridaje panera
A13: Salame artesanal (pieza) | B13: 9500 | C13: 10 | D13: =B13/C13 | E13: 5500 | F13: =E13-D13 | G13: =F13/E13 | H13: Base: maridaje salame
A14: PROMEDIO | B14: =AVERAGE(B3:B13) | C14: =AVERAGE(C3:C13) | D14: =AVERAGE(D3:D13) | E14: =AVERAGE(E3:E13) | F14: =AVERAGE(F3:F13) | G14: =AVERAGE(G3:G13)
A17: APORTE DEL TAPEO AL TICKET PROMEDIO
A18: % de clientes que piden tapeo | B18: =PctClientesTapeo
A19: Ticket tapeo promedio por pedido | B19: =AVERAGE(E3:E13)
A20: % costo promedio del tapeo s/precio de venta | B20: =AVERAGE(D3:D13)/AVERAGE(E3:E13)
A21: Ticket copas promedio por persona (referencia) | B21: =CopasPorPersona*'CARTA SEMANAL'!PrecioVentaPromedio
A22: Aporte del tapeo al ticket total por persona (%) | B22: =(PctClientesTapeo*B19)/(B21+PctClientesTapeo*B19)

Sheet COSTOS FIJOS Y VARIABLES
A1: COSTOS FIJOS Y VARIABLES — desglose mensual
A2: SUPUESTOS DE FACTURACIÓN BASE (para calcular variables)
A3: Copas vendidas por mes (escenario base) | B3: =PersonasPorNocheBase*CopasPorPersona*NochesPorMes
A4: Facturación mensual estimada por copas (escenario base) | B4: =CopasVendidasMesBase*'CARTA SEMANAL'!PrecioVentaPromedio
A6: Rubro | B6: Monto mensual | C6: Escala con 5ta noche | D6: Nota
A7: COSTOS FIJOS
A8: Alquiler | B8: =Alquiler | C8: No
A9: Sueldos y cargas sociales (base, 4 noches) | B9: =SueldosCargas | C9: No
A10: Personal de apoyo — 5ta noche | B10: =PersonalApoyo5taNoche | C10: Sí | D10: Turno extra de sala/bacha
A11: Servicios (luz/gas/agua/internet) | B11: =Servicios | C11: No
A12: Servicios extra — 5ta noche | B12: =ServiciosExtra5taNoche | C12: Sí | D12: Mayor consumo por noche extra
A13: Impuestos y tasas municipales | B13: =ImpuestosTasas | C13: No
A14: Seguro | B14: =Seguro | C14: No
A15: Contador | B15: =Contador | C15: No
A16: Mantenimiento dispenser Redsack | B16: =MantenimientoDispenser | C16: No
A17: Marketing / redes | B17: =MarketingRedes | C17: No
A18: SUBTOTAL COSTOS FIJOS (con 5ta noche) | B18: =SUM(B8:B17)
A19: Total costos fijos SIN 5ta noche (referencia, 4 noches/sem) | B19: =B18-PersonalApoyo5taNoche-ServiciosExtra5taNoche
A20: Diferencia vs. piso de referencia del dueño ($3.000.000) | B20: =B18-CostosFijosReferencia
A22: COSTOS VARIABLES
A23: Insumos de limpieza (por noche operada) | B23: =CostoLimpiezaPorNoche*NochesPorMes | C23: Sí | D23: Escala con noches operadas (incluida la 5ta)
A24: Cristalería de reposición (roturas) | B24: =CopasVendidasMesBase*PctRoturasCristaleria*CostoReposicionCopaUnidad | C24: Sí | D24: Escala con volumen de copas servidas
A25: Comisión medios de pago | B25: =FacturacionMensualBase*PctComisionMedioPago | C25: Sí | D25: Escala con facturación
A26: SUBTOTAL COSTOS VARIABLES (escenario base) | B26: =SUM(B23:B25)
A27: TOTAL FIJOS + VARIABLES (escenario base, 5 noches) | B27: =B18+B26

Sheet PUNTO DE EQUILIBRIO
A1: PUNTO DE EQUILIBRIO — copas, pesos y personas por noche
A2: SUPUESTOS COMUNES
A3: Precio de venta promedio ponderado | B3: ='CARTA SEMANAL'!PrecioVentaPromedio
A4: Precio góndola promedio | B4: ='CARTA SEMANAL'!PrecioGondolaPromedio
A5: Costo de botella de compra (% s/góndola promedio) | B5: ='CARTA SEMANAL'!PrecioGondolaPromedio*PctCostoVinoPropio
A6: Costo por copa — vino de compra (rendimiento real) | B6: =B5/RendimientoRealCopasPorBotella
A7: Comisión medios de pago por copa (s/precio venta prom.) | B7: ='CARTA SEMANAL'!PrecioVentaPromedio*PctComisionMedioPago
A9: Concepto | B9: Mix 0% socias | C9: Mix 50% socias | D9: Mix 100% socias
A10: % bodegas socias (mix del escenario) | B10: 0 | C10: 0.5 | D10: 1
A11: Costo variable de vino por copa | B11: =(1-B10)*CostoPorCopaCompraPromedio | C11: =(1-C10)*CostoPorCopaCompraPromedio | D11: =(1-D10)*CostoPorCopaCompraPromedio
A12: Comisión medios de pago por copa | B12: =$B$7 | C12: =$B$7 | D12: =$B$7
A13: Costo variable total por copa | B13: =B11+B12 | C13: =C11+C12 | D13: =D11+D12
A14: Margen de contribución por copa | B14: ='CARTA SEMANAL'!PrecioVentaPromedio-B13 | C14: ='CARTA SEMANAL'!PrecioVentaPromedio-C13 | D14: ='CARTA SEMANAL'!PrecioVentaPromedio-D13
A16: EQUILIBRIO CON 5 NOCHES / SEMANA (costos fijos actuales)
A17: Costos fijos mensuales (5 noches) | B17: ='COSTOS FIJOS Y VARIABLES'!TotalCostosFijos5Noches | C17: ='COSTOS FIJOS Y VARIABLES'!TotalCostosFijos5Noches | D17: ='COSTOS FIJOS Y VARIABLES'!TotalCostosFijos5Noches
A18: Equilibrio: copas por mes | B18: =B17/B14 | C18: =C17/C14 | D18: =D17/D14
A19: Equilibrio: copas por noche | B19: =B18/NochesPorMes | C19: =C18/NochesPorMes | D19: =D18/NochesPorMes
A20: Equilibrio: facturación mensual | B20: =B18*'CARTA SEMANAL'!PrecioVentaPromedio | C20: =C18*'CARTA SEMANAL'!PrecioVentaPromedio | D20: =D18*'CARTA SEMANAL'!PrecioVentaPromedio
A21: Equilibrio: personas por noche | B21: =B19/CopasPorPersona | C21: =C19/CopasPorPersona | D21: =D19/CopasPorPersona
A23: EQUILIBRIO SIN 5ta NOCHE (referencia, 4 noches/semana)
A24: Costos fijos mensuales (sin 5ta noche) | B24: ='COSTOS FIJOS Y VARIABLES'!TotalCostosFijosSin5taNoche | C24: ='COSTOS FIJOS Y VARIABLES'!TotalCostosFijosSin5taNoche | D24: ='COSTOS FIJOS Y VARIABLES'!TotalCostosFijosSin5taNoche
A25: Equilibrio: copas por mes | B25: =B24/B14 | C25: =C24/C14 | D25: =D24/D14
A26: Equilibrio: copas por noche | B26: =B25/NochesPorMesAlt | C26: =C25/NochesPorMesAlt | D26: =D25/NochesPorMesAlt
A27: Equilibrio: personas por noche | B27: =B26/CopasPorPersona | C27: =C26/CopasPorPersona | D27: =D26/CopasPorPersona
A29: EFECTO NETO DE LA 5ta NOCHE (mix 50% socias)
A30: Δ Equilibrio en personas/noche (5 noches vs. 4 noches) | B30: =C21-C27
A31: Δ Costo fijo mensual (5 noches vs. 4 noches) | B31: =C17-C24
A32: La 5ta noche baja el equilibrio POR NOCHE (el costo fijo se reparte en más noches), pero sube el costo fijo MENSUAL total (personal y servicios extra). El resultado neto depende de si esa noche adicional genera suficiente contribución marginal para cubrir su propio costo incremental — ver hoja RENTABILIDAD POR NOCHE.

Sheet RENTABILIDAD POR NOCHE
A1: RENTABILIDAD POR NOCHE — martes a sábado
A2: Día | B2: Personas estimadas | C2: Copas vendidas | D2: Ingreso copas | E2: Ingreso tapeo | F2: Ingreso total | G2: Costo var. vino | H2: Costo var. tapeo | I2: Comisión medios pago | J2: Costo var. total | K2: Contrib. marg. noche | L2: Ocurrencias /mes | M2: Costo fijo asignado/mes | N2: Contrib. marg. mensual | O2: Resultado mensual | P2: Simular cierre | Q2: Impacto si se cierra ($/mes)
A3: Martes | B3: 20 | C3: =B3*CopasPorPersona | D3: =C3*'CARTA SEMANAL'!PrecioVentaPromedio | E3: =B3*PctClientesTapeo*TAPEO!TicketTapeoPromedio | F3: =D3+E3 | G3: =C3*'PUNTO DE EQUILIBRIO'!CostoPorCopaCompraPromedio*(1-PctBodegasSocias) | H3: =E3*TAPEO!TapeoCostoPct | I3: =F3*PctComisionMedioPago | J3: =G3+H3+I3 | K3: =F3-J3 | L3: =NochesPorMes/5 | M3: ='COSTOS FIJOS Y VARIABLES'!TotalCostosFijos5Noches/5 | N3: =K3*L3 | O3: =N3-M3 | P3: No | Q3: =IF(P3="Sí",-N3+PersonalApoyo5taNoche+ServiciosExtra5taNoche,0)
A4: Miércoles | B4: 24 | C4: =B4*CopasPorPersona | D4: =C4*'CARTA SEMANAL'!PrecioVentaPromedio | E4: =B4*PctClientesTapeo*TAPEO!TicketTapeoPromedio | F4: =D4+E4 | G4: =C4*'PUNTO DE EQUILIBRIO'!CostoPorCopaCompraPromedio*(1-PctBodegasSocias) | H4: =E4*TAPEO!TapeoCostoPct | I4: =F4*PctComisionMedioPago | J4: =G4+H4+I4 | K4: =F4-J4 | L4: =NochesPorMes/5 | M4: ='COSTOS FIJOS Y VARIABLES'!TotalCostosFijos5Noches/5 | N4: =K4*L4 | O4: =N4-M4 | P4: No | Q4: =IF(P4="Sí",-N4,0)
A5: Jueves | B5: 30 | C5: =B5*CopasPorPersona | D5: =C5*'CARTA SEMANAL'!PrecioVentaPromedio | E5: =B5*PctClientesTapeo*TAPEO!TicketTapeoPromedio | F5: =D5+E5 | G5: =C5*'PUNTO DE EQUILIBRIO'!CostoPorCopaCompraPromedio*(1-PctBodegasSocias) | H5: =E5*TAPEO!TapeoCostoPct | I5: =F5*PctComisionMedioPago | J5: =G5+H5+I5 | K5: =F5-J5 | L5: =NochesPorMes/5 | M5: ='COSTOS FIJOS Y VARIABLES'!TotalCostosFijos5Noches/5 | N5: =K5*L5 | O5: =N5-M5 | P5: No | Q5: =IF(P5="Sí",-N5,0)
A6: Viernes | B6: 45 | C6: =B6*CopasPorPersona | D6: =C6*'CARTA SEMANAL'!PrecioVentaPromedio | E6: =B6*PctClientesTapeo*TAPEO!TicketTapeoPromedio | F6: =D6+E6 | G6: =C6*'PUNTO DE EQUILIBRIO'!CostoPorCopaCompraPromedio*(1-PctBodegasSocias) | H6: =E6*TAPEO!TapeoCostoPct | I6: =F6*PctComisionMedioPago | J6: =G6+H6+I6 | K6: =F6-J6 | L6: =NochesPorMes/5 | M6: ='COSTOS FIJOS Y VARIABLES'!TotalCostosFijos5Noches/5 | N6: =K6*L6 | O6: =N6-M6 | P6: No | Q6: =IF(P6="Sí",-N6,0)
A7: Sábado | B7: 50 | C7: =B7*CopasPorPersona | D7: =C7*'CARTA SEMANAL'!PrecioVentaPromedio | E7: =B7*PctClientesTapeo*TAPEO!TicketTapeoPromedio | F7: =D7+E7 | G7: =C7*'PUNTO DE EQUILIBRIO'!CostoPorCopaCompraPromedio*(1-PctBodegasSocias) | H7: =E7*TAPEO!TapeoCostoPct | I7: =F7*PctComisionMedioPago | J7: =G7+H7+I7 | K7: =F7-J7 | L7: =NochesPorMes/5 | M7: ='COSTOS FIJOS Y VARIABLES'!TotalCostosFijos5Noches/5 | N7: =K7*L7 | O7: =N7-M7 | P7: No | Q7: =IF(P7="Sí",-N7,0)
A8: TOTAL SEMANA | B8: =SUM(B3:B7) | C8: =SUM(C3:C7) | D8: =SUM(D3:D7) | E8: =SUM(E3:E7) | F8: =SUM(F3:F7) | G8: =SUM(G3:G7) | H8: =SUM(H3:H7) | I8: =SUM(I3:I7) | ... K8: =SUM(K3:K7) | N8: =SUM(N3:N7) | O8: =SUM(O3:O7) | Q8: =SUM(Q3:Q7)
A10: Resultado mensual total (sin simular cierres) | E10: =SUM(O3:O7)
A11: Resultado mensual simulado (con cierres marcados) | E11: =E10+SUM(Q3:Q7)
A12: Diferencia por cierres simulados | E12: =E11-E10
A14: Martes está marcado como la noche marginal (5ta noche agregada al horario de 4 noches). Si se simula su cierre, además de perder su contribución marginal mensual se ahorra el personal de apoyo y el extra de servicios de la 5ta noche. Para las demás noches, cerrarla solo resta su contribución marginal — el resto de los costos fijos no cambia.

Sheet P&L MENSUAL PROYECTADO
A1: P&L MENSUAL PROYECTADO — 12 meses, con estacionalidad de Mar del Plata
A2: Concepto | B2: Ene | C2: Feb | D2: Mar | E2: Abr | F2: May | G2: Jun | H2: Jul | I2: Ago | J2: Sep | K2: Oct | L2: Nov | M2: Dic
A3: Índice estacional | B3: =IdxEne | C3: =IdxFeb | D3: =IdxMar | E3: =IdxAbr | F3: =IdxMay | G3: =IdxJun | H3: =IdxJul | I3: =IdxAgo | J3: =IdxSep | K3: =IdxOct | L3: =IdxNov | M3: =IdxDic
A4: Copas vendidas (mes) | B4: ='COSTOS FIJOS Y VARIABLES'!CopasVendidasMesBase*B3 | C4: ='COSTOS FIJOS Y VARIABLES'!CopasVendidasMesBase*C3 | D4: ='COSTOS FIJOS Y VARIABLES'!CopasVendidasMesBase*D3 | E4: ='COSTOS FIJOS Y VARIABLES'!CopasVendidasMesBase*E3 | F4: ='COSTOS FIJOS Y VARIABLES'!CopasVendidasMesBase*F3 | G4: ='COSTOS FIJOS Y VARIABLES'!CopasVendidasMesBase*G3 | H4: ='COSTOS FIJOS Y VARIABLES'!CopasVendidasMesBase*H3 | I4: ='COSTOS FIJOS Y VARIABLES'!CopasVendidasMesBase*I3 | ... M4: ='COSTOS FIJOS Y VARIABLES'!CopasVendidasMesBase*M3
A5: Socios club activos (auxiliar) | B5: =ROUND(ClubSociosInicial+(ClubSociosFinal-ClubSociosInicial)*(COLUMN()-2)/11,0) | C5: =ROUND(ClubSociosInicial+(ClubSociosFinal-ClubSociosInicial)*(COLUMN()-2)/11,0) | D5: =ROUND(ClubSociosInicial+(ClubSociosFinal-ClubSociosInicial)*(COLUMN()-2)/11,0) | E5: =ROUND(ClubSociosInicial+(ClubSociosFinal-ClubSociosInicial)*(COLUMN()-2)/11,0) | F5: =ROUND(ClubSociosInicial+(ClubSociosFinal-ClubSociosInicial)*(COLUMN()-2)/11,0) | G5: =ROUND(ClubSociosInicial+(ClubSociosFinal-ClubSociosInicial)*(COLUMN()-2)/11,0) | H5: =ROUND(ClubSociosInicial+(ClubSociosFinal-ClubSociosInicial)*(COLUMN()-2)/11,0) | I5: =ROUND(ClubSociosInicial+(ClubSociosFinal-ClubSociosInicial)*(COLUMN()-2)/11,0) | ... M5: =ROUND(ClubSociosInicial+(ClubSociosFinal-ClubSociosInicial)*(COLUMN()-2)/11,0)
A7: INGRESOS
A8: Ingreso por copa | B8: =B4*'CARTA SEMANAL'!PrecioVentaPromedio | C8: =C4*'CARTA SEMANAL'!PrecioVentaPromedio | D8: =D4*'CARTA SEMANAL'!PrecioVentaPromedio | E8: =E4*'CARTA SEMANAL'!PrecioVentaPromedio | F8: =F4*'CARTA SEMANAL'!PrecioVentaPromedio | G8: =G4*'CARTA SEMANAL'!PrecioVentaPromedio | H8: =H4*'CARTA SEMANAL'!PrecioVentaPromedio | I8: =I4*'CARTA SEMANAL'!PrecioVentaPromedio | ... M8: =M4*'CARTA SEMANAL'!PrecioVentaPromedio
A9: Ingreso tapeo | B9: =(B4/CopasPorPersona)*PctClientesTapeo*TAPEO!TicketTapeoPromedio | C9: =(C4/CopasPorPersona)*PctClientesTapeo*TAPEO!TicketTapeoPromedio | D9: =(D4/CopasPorPersona)*PctClientesTapeo*TAPEO!TicketTapeoPromedio | E9: =(E4/CopasPorPersona)*PctClientesTapeo*TAPEO!TicketTapeoPromedio | F9: =(F4/CopasPorPersona)*PctClientesTapeo*TAPEO!TicketTapeoPromedio | G9: =(G4/CopasPorPersona)*PctClientesTapeo*TAPEO!TicketTapeoPromedio | H9: =(H4/CopasPorPersona)*PctClientesTapeo*TAPEO!TicketTapeoPromedio | I9: =(I4/CopasPorPersona)*PctClientesTapeo*TAPEO!TicketTapeoPromedio | ... M9: =(M4/CopasPorPersona)*PctClientesTapeo*TAPEO!TicketTapeoPromedio
A10: Ingreso club de socios | B10: =B5*ClubSociosCuotaPromedio | C10: =C5*ClubSociosCuotaPromedio | D10: =D5*ClubSociosCuotaPromedio | E10: =E5*ClubSociosCuotaPromedio | F10: =F5*ClubSociosCuotaPromedio | G10: =G5*ClubSociosCuotaPromedio | H10: =H5*ClubSociosCuotaPromedio | I10: =I5*ClubSociosCuotaPromedio | ... M10: =M5*ClubSociosCuotaPromedio
A11: Ingreso eventos (alquiler del espacio) | B11: =IngresoEventosMensual | C11: =IngresoEventosMensual | D11: =IngresoEventosMensual | E11: =IngresoEventosMensual | F11: =IngresoEventosMensual | G11: =IngresoEventosMensual | H11: =IngresoEventosMensual | I11: =IngresoEventosMensual | ... M11: =IngresoEventosMensual
A12: TOTAL INGRESOS | B12: =SUM(B8:B11) | C12: =SUM(C8:C11) | D12: =SUM(D8:D11) | E12: =SUM(E8:E11) | F12: =SUM(F8:F11) | G12: =SUM(G8:G11) | H12: =SUM(H8:H11) | I12: =SUM(I8:I11) | ... M12: =SUM(M8:M11)
A14: COSTOS
A15: Costo de vino | B15: =B4*'PUNTO DE EQUILIBRIO'!CostoPorCopaCompraPromedio*(1-PctBodegasSocias)*(1+InflacionMensual)^(COLUMN()-2) | C15: =C4*'PUNTO DE EQUILIBRIO'!CostoPorCopaCompraPromedio*(1-PctBodegasSocias)*(1+InflacionMensual)^(COLUMN()-2) | D15: =D4*'PUNTO DE EQUILIBRIO'!CostoPorCopaCompraPromedio*(1-PctBodegasSocias)*(1+InflacionMensual)^(COLUMN()-2) | E15: =E4*'PUNTO DE EQUILIBRIO'!CostoPorCopaCompraPromedio*(1-PctBodegasSocias)*(1+InflacionMensual)^(COLUMN()-2) | F15: =F4*'PUNTO DE EQUILIBRIO'!CostoPorCopaCompraPromedio*(1-PctBodegasSocias)*(1+InflacionMensual)^(COLUMN()-2) | G15: =G4*'PUNTO DE EQUILIBRIO'!CostoPorCopaCompraPromedio*(1-PctBodegasSocias)*(1+InflacionMensual)^(COLUMN()-2) | H15: =H4*'PUNTO DE EQUILIBRIO'!CostoPorCopaCompraPromedio*(1-PctBodegasSocias)*(1+InflacionMensual)^(COLUMN()-2) | I15: =I4*'PUNTO DE EQUILIBRIO'!CostoPorCopaCompraPromedio*(1-PctBodegasSocias)*(1+InflacionMensual)^(COLUMN()-2) | ... M15: =M4*'PUNTO DE EQUILIBRIO'!CostoPorCopaCompraPromedio*(1-PctBodegasSocias)*(1+InflacionMensual)^(COLUMN()-2)
A16: Costo de tapeo | B16: =B9*TAPEO!TapeoCostoPct*(1+InflacionMensual)^(COLUMN()-2) | C16: =C9*TAPEO!TapeoCostoPct*(1+InflacionMensual)^(COLUMN()-2) | D16: =D9*TAPEO!TapeoCostoPct*(1+InflacionMensual)^(COLUMN()-2) | E16: =E9*TAPEO!TapeoCostoPct*(1+InflacionMensual)^(COLUMN()-2) | F16: =F9*TAPEO!TapeoCostoPct*(1+InflacionMensual)^(COLUMN()-2) | G16: =G9*TAPEO!TapeoCostoPct*(1+InflacionMensual)^(COLUMN()-2) | H16: =H9*TAPEO!TapeoCostoPct*(1+InflacionMensual)^(COLUMN()-2) | I16: =I9*TAPEO!TapeoCostoPct*(1+InflacionMensual)^(COLUMN()-2) | ... M16: =M9*TAPEO!TapeoCostoPct*(1+InflacionMensual)^(COLUMN()-2)
A17: · Comisión medios de pago (auxiliar) | B17: =B12*PctComisionMedioPago | C17: =C12*PctComisionMedioPago | D17: =D12*PctComisionMedioPago | E17: =E12*PctComisionMedioPago | F17: =F12*PctComisionMedioPago | G17: =G12*PctComisionMedioPago | H17: =H12*PctComisionMedioPago | I17: =I12*PctComisionMedioPago | ... M17: =M12*PctComisionMedioPago
A18: · Insumos de limpieza (auxiliar) | B18: =CostoLimpiezaPorNoche*NochesPorMes*(1+InflacionMensual)^(COLUMN()-2) | C18: =CostoLimpiezaPorNoche*NochesPorMes*(1+InflacionMensual)^(COLUMN()-2) | D18: =CostoLimpiezaPorNoche*NochesPorMes*(1+InflacionMensual)^(COLUMN()-2) | E18: =CostoLimpiezaPorNoche*NochesPorMes*(1+InflacionMensual)^(COLUMN()-2) | F18: =CostoLimpiezaPorNoche*NochesPorMes*(1+InflacionMensual)^(COLUMN()-2) | G18: =CostoLimpiezaPorNoche*NochesPorMes*(1+InflacionMensual)^(COLUMN()-2) | H18: =CostoLimpiezaPorNoche*NochesPorMes*(1+InflacionMensual)^(COLUMN()-2) | I18: =CostoLimpiezaPorNoche*NochesPorMes*(1+InflacionMensual)^(COLUMN()-2) | ... M18: =CostoLimpiezaPorNoche*NochesPorMes*(1+InflacionMensual)^(COLUMN()-2)
A19: · Cristalería de reposición (auxiliar) | B19: =B4*PctRoturasCristaleria*CostoReposicionCopaUnidad*(1+InflacionMensual)^(COLUMN()-2) | C19: =C4*PctRoturasCristaleria*CostoReposicionCopaUnidad*(1+InflacionMensual)^(COLUMN()-2) | D19: =D4*PctRoturasCristaleria*CostoReposicionCopaUnidad*(1+InflacionMensual)^(COLUMN()-2) | E19: =E4*PctRoturasCristaleria*CostoReposicionCopaUnidad*(1+InflacionMensual)^(COLUMN()-2) | F19: =F4*PctRoturasCristaleria*CostoReposicionCopaUnidad*(1+InflacionMensual)^(COLUMN()-2) | G19: =G4*PctRoturasCristaleria*CostoReposicionCopaUnidad*(1+InflacionMensual)^(COLUMN()-2) | H19: =H4*PctRoturasCristaleria*CostoReposicionCopaUnidad*(1+InflacionMensual)^(COLUMN()-2) | I19: =I4*PctRoturasCristaleria*CostoReposicionCopaUnidad*(1+InflacionMensual)^(COLUMN()-2) | ... M19: =M4*PctRoturasCristaleria*CostoReposicionCopaUnidad*(1+InflacionMensual)^(COLUMN()-2)
A20: Costos variables (total) | B20: =B17+B18+B19 | C20: =C17+C18+C19 | D20: =D17+D18+D19 | E20: =E17+E18+E19 | F20: =F17+F18+F19 | G20: =G17+G18+G19 | H20: =H17+H18+H19 | I20: =I17+I18+I19 | ... M20: =M17+M18+M19
A21: Costos fijos | B21: ='COSTOS FIJOS Y VARIABLES'!TotalCostosFijos5Noches*(1+InflacionMensual)^(COLUMN()-2) | C21: ='COSTOS FIJOS Y VARIABLES'!TotalCostosFijos5Noches*(1+InflacionMensual)^(COLUMN()-2) | D21: ='COSTOS FIJOS Y VARIABLES'!TotalCostosFijos5Noches*(1+InflacionMensual)^(COLUMN()-2) | E21: ='COSTOS FIJOS Y VARIABLES'!TotalCostosFijos5Noches*(1+InflacionMensual)^(COLUMN()-2) | F21: ='COSTOS FIJOS Y VARIABLES'!TotalCostosFijos5Noches*(1+InflacionMensual)^(COLUMN()-2) | G21: ='COSTOS FIJOS Y VARIABLES'!TotalCostosFijos5Noches*(1+InflacionMensual)^(COLUMN()-2) | H21: ='COSTOS FIJOS Y VARIABLES'!TotalCostosFijos5Noches*(1+InflacionMensual)^(COLUMN()-2) | I21: ='COSTOS FIJOS Y VARIABLES'!TotalCostosFijos5Noches*(1+InflacionMensual)^(COLUMN()-2) | ... M21: ='COSTOS FIJOS Y VARIABLES'!TotalCostosFijos5Noches*(1+InflacionMensual)^(COLUMN()-2)
A23: RESULTADO
A24: RESULTADO OPERATIVO | B24: =B12-B15-B16-B20-B21 | C24: =C12-C15-C16-C20-C21 | D24: =D12-D15-D16-D20-D21 | E24: =E12-E15-E16-E20-E21 | F24: =F12-F15-F16-F20-F21 | G24: =G12-G15-G16-G20-G21 | H24: =H12-H15-H16-H20-H21 | I24: =I12-I15-I16-I20-I21 | ... M24: =M12-M15-M16-M20-M21
A25: Margen neto % | B25: =B24/B12 | C25: =C24/C12 | D25: =D24/D12 | E25: =E24/E12 | F25: =F24/F12 | G25: =G24/G12 | H25: =H24/H12 | I25: =I24/I12 | ... M25: =M24/M12
A26: Acumulado | B26: =SUM($B$24:B24) | C26: =SUM($B$24:C24) | D26: =SUM($B$24:D24) | E26: =SUM($B$24:E24) | F26: =SUM($B$24:F24) | G26: =SUM($B$24:G24) | H26: =SUM($B$24:H24) | I26: =SUM($B$24:I24) | ... M26: =SUM($B$24:M24)

Sheet ESCENARIOS
A1: ESCENARIOS — pesimista / base / optimista
A2: Concepto | B2: Pesimista | C2: Base | D2: Optimista
A3: Personas por noche | B3: 25 | C3: =PersonasPorNocheBase | D3: 55
A4: Copas por persona | B4: 1.8 | C4: =CopasPorPersona | D4: 2.6
A5: % bodegas socias en carta | B5: 0.3 | C5: =PctBodegasSocias | D5: 0.6
A6: Ticket tapeo promedio | B6: =TAPEO!TicketTapeoPromedio*0.7 | C6: =TAPEO!TicketTapeoPromedio | D6: =TAPEO!TicketTapeoPromedio*1.3
A8: PROYECCIÓN MENSUAL RESULTANTE
A9: Copas vendidas por mes | B9: =B3*B4*NochesPorMes | C9: =C3*C4*NochesPorMes | D9: =D3*D4*NochesPorMes
A10: Precio venta promedio | B10: ='CARTA SEMANAL'!PrecioVentaPromedio | C10: ='CARTA SEMANAL'!PrecioVentaPromedio | D10: ='CARTA SEMANAL'!PrecioVentaPromedio
A11: Costo por copa (según mix de socias) | B11: ='PUNTO DE EQUILIBRIO'!CostoPorCopaCompraPromedio*(1-B5) | C11: ='PUNTO DE EQUILIBRIO'!CostoPorCopaCompraPromedio*(1-C5) | D11: ='PUNTO DE EQUILIBRIO'!CostoPorCopaCompraPromedio*(1-D5)
A12: Ingreso copas mensual | B12: =B9*'CARTA SEMANAL'!PrecioVentaPromedio | C12: =C9*'CARTA SEMANAL'!PrecioVentaPromedio | D12: =D9*'CARTA SEMANAL'!PrecioVentaPromedio
A13: Ingreso tapeo mensual | B13: =B3*NochesPorMes*PctClientesTapeo*B6 | C13: =C3*NochesPorMes*PctClientesTapeo*C6 | D13: =D3*NochesPorMes*PctClientesTapeo*D6
A14: Ingreso club de socios mensual (prom. anual) | B14: =((ClubSociosInicial+ClubSociosFinal)/2)*ClubSociosCuotaPromedio | C14: =((ClubSociosInicial+ClubSociosFinal)/2)*ClubSociosCuotaPromedio | D14: =((ClubSociosInicial+ClubSociosFinal)/2)*ClubSociosCuotaPromedio
A15: Ingreso eventos mensual | B15: =IngresoEventosMensual | C15: =IngresoEventosMensual | D15: =IngresoEventosMensual
A16: TOTAL INGRESOS | B16: =SUM(B12:B15) | C16: =SUM(C12:C15) | D16: =SUM(D12:D15)
A17: Costo de vino mensual | B17: =B9*B11 | C17: =C9*C11 | D17: =D9*D11
A18: Costo de tapeo mensual | B18: =B13*TAPEO!TapeoCostoPct | C18: =C13*TAPEO!TapeoCostoPct | D18: =D13*TAPEO!TapeoCostoPct
A19: Costos variables (comisión + limpieza + cristalería) | B19: =B16*PctComisionMedioPago+CostoLimpiezaPorNoche*NochesPorMes+B9*PctRoturasCristaleria*CostoReposicionCopaUnidad | C19: =C16*PctComisionMedioPago+CostoLimpiezaPorNoche*NochesPorMes+C9*PctRoturasCristaleria*CostoReposicionCopaUnidad | D19: =D16*PctComisionMedioPago+CostoLimpiezaPorNoche*NochesPorMes+D9*PctRoturasCristaleria*CostoReposicionCopaUnidad
A20: Costos fijos | B20: ='COSTOS FIJOS Y VARIABLES'!TotalCostosFijos5Noches | C20: ='COSTOS FIJOS Y VARIABLES'!TotalCostosFijos5Noches | D20: ='COSTOS FIJOS Y VARIABLES'!TotalCostosFijos5Noches
A21: RESULTADO OPERATIVO | B21: =B16-B17-B18-B19-B20 | C21: =C16-C17-C18-C19-C20 | D21: =D16-D17-D18-D19-D20
A22: Margen neto % | B22: =B21/B16 | C22: =C21/C16 | D22: =D21/D16
